2020-07-28 22:12:55,313 ERROR: Exception on /results [GET] [in /Library/Frameworks/Python.framework/Versions/3.8/lib/python3.8/site-packages/flask/app.py:1891]
Traceback (most recent call last):
  File "/Library/Frameworks/Python.framework/Versions/3.8/lib/python3.8/site-packages/flask/app.py", line 2447, in wsgi_app
    response = self.full_dispatch_request()
  File "/Library/Frameworks/Python.framework/Versions/3.8/lib/python3.8/site-packages/flask/app.py", line 1952, in full_dispatch_request
    rv = self.handle_user_exception(e)
  File "/Library/Frameworks/Python.framework/Versions/3.8/lib/python3.8/site-packages/flask/app.py", line 1821, in handle_user_exception
    reraise(exc_type, exc_value, tb)
  File "/Library/Frameworks/Python.framework/Versions/3.8/lib/python3.8/site-packages/flask/_compat.py", line 39, in reraise
    raise value
  File "/Library/Frameworks/Python.framework/Versions/3.8/lib/python3.8/site-packages/flask/app.py", line 1950, in full_dispatch_request
    rv = self.dispatch_request()
  File "/Library/Frameworks/Python.framework/Versions/3.8/lib/python3.8/site-packages/flask/app.py", line 1936, in dispatch_request
    return self.view_functions[rule.endpoint](**req.view_args)
  File "/Users/jacquelynchow/personalprojects/recipe-scraper/app/routes.py", line 137, in recipeResults
    return render_template('recipeResults.html', toReturn=toReturn, keyword_search=keyword_search)
  File "/Library/Frameworks/Python.framework/Versions/3.8/lib/python3.8/site-packages/flask/templating.py", line 137, in render_template
    return _render(
  File "/Library/Frameworks/Python.framework/Versions/3.8/lib/python3.8/site-packages/flask/templating.py", line 120, in _render
    rv = template.render(context)
  File "/Library/Frameworks/Python.framework/Versions/3.8/lib/python3.8/site-packages/jinja2/environment.py", line 1090, in render
    self.environment.handle_exception()
  File "/Library/Frameworks/Python.framework/Versions/3.8/lib/python3.8/site-packages/jinja2/environment.py", line 832, in handle_exception
    reraise(*rewrite_traceback_stack(source=source))
  File "/Library/Frameworks/Python.framework/Versions/3.8/lib/python3.8/site-packages/jinja2/_compat.py", line 28, in reraise
    raise value.with_traceback(tb)
  File "/Users/jacquelynchow/personalprojects/recipe-scraper/app/templates/recipeResults.html", line 2, in top-level template code
    {% set active_page = "recipeResults" %}
  File "/Users/jacquelynchow/personalprojects/recipe-scraper/app/templates/layout.html", line 72, in top-level template code
    {% block body %}
  File "/Users/jacquelynchow/personalprojects/recipe-scraper/app/templates/recipeResults.html", line 48, in block "body"
    {% if current_user.is_following(recipe) %}
  File "/Users/jacquelynchow/personalprojects/recipe-scraper/app/models.py", line 74, in is_following
    saved_recipes.c.recipe_id == recipe.id).count() > 0
jinja2.exceptions.UndefinedError: 'recipe' is undefined
2020-07-28 22:15:44,450 INFO: Recipe App startup [in /Users/jacquelynchow/personalprojects/recipe-scraper/app/__init__.py:63]
2020-07-28 22:17:03,259 INFO: Recipe App startup [in /Users/jacquelynchow/personalprojects/recipe-scraper/app/__init__.py:63]
2020-07-28 22:17:09,849 ERROR: Exception on /saves [POST] [in /Library/Frameworks/Python.framework/Versions/3.8/lib/python3.8/site-packages/flask/app.py:1891]
Traceback (most recent call last):
  File "/Library/Frameworks/Python.framework/Versions/3.8/lib/python3.8/site-packages/flask/app.py", line 2447, in wsgi_app
    response = self.full_dispatch_request()
  File "/Library/Frameworks/Python.framework/Versions/3.8/lib/python3.8/site-packages/flask/app.py", line 1952, in full_dispatch_request
    rv = self.handle_user_exception(e)
  File "/Library/Frameworks/Python.framework/Versions/3.8/lib/python3.8/site-packages/flask/app.py", line 1821, in handle_user_exception
    reraise(exc_type, exc_value, tb)
  File "/Library/Frameworks/Python.framework/Versions/3.8/lib/python3.8/site-packages/flask/_compat.py", line 39, in reraise
    raise value
  File "/Library/Frameworks/Python.framework/Versions/3.8/lib/python3.8/site-packages/flask/app.py", line 1950, in full_dispatch_request
    rv = self.dispatch_request()
  File "/Library/Frameworks/Python.framework/Versions/3.8/lib/python3.8/site-packages/flask/app.py", line 1936, in dispatch_request
    return self.view_functions[rule.endpoint](**req.view_args)
  File "/Library/Frameworks/Python.framework/Versions/3.8/lib/python3.8/site-packages/flask_login/utils.py", line 272, in decorated_view
    return func(*args, **kwargs)
  File "/Users/jacquelynchow/personalprojects/recipe-scraper/app/routes.py", line 193, in saves
    recipe = Recipe.query.filter_by(id=int(recipeID)).first_or_404()
ValueError: invalid literal for int() with base 10: 'saves1023'
2020-07-28 22:17:10,610 ERROR: Exception on /saves [POST] [in /Library/Frameworks/Python.framework/Versions/3.8/lib/python3.8/site-packages/flask/app.py:1891]
Traceback (most recent call last):
  File "/Library/Frameworks/Python.framework/Versions/3.8/lib/python3.8/site-packages/flask/app.py", line 2447, in wsgi_app
    response = self.full_dispatch_request()
  File "/Library/Frameworks/Python.framework/Versions/3.8/lib/python3.8/site-packages/flask/app.py", line 1952, in full_dispatch_request
    rv = self.handle_user_exception(e)
  File "/Library/Frameworks/Python.framework/Versions/3.8/lib/python3.8/site-packages/flask/app.py", line 1821, in handle_user_exception
    reraise(exc_type, exc_value, tb)
  File "/Library/Frameworks/Python.framework/Versions/3.8/lib/python3.8/site-packages/flask/_compat.py", line 39, in reraise
    raise value
  File "/Library/Frameworks/Python.framework/Versions/3.8/lib/python3.8/site-packages/flask/app.py", line 1950, in full_dispatch_request
    rv = self.dispatch_request()
  File "/Library/Frameworks/Python.framework/Versions/3.8/lib/python3.8/site-packages/flask/app.py", line 1936, in dispatch_request
    return self.view_functions[rule.endpoint](**req.view_args)
  File "/Library/Frameworks/Python.framework/Versions/3.8/lib/python3.8/site-packages/flask_login/utils.py", line 272, in decorated_view
    return func(*args, **kwargs)
  File "/Users/jacquelynchow/personalprojects/recipe-scraper/app/routes.py", line 193, in saves
    recipe = Recipe.query.filter_by(id=int(recipeID)).first_or_404()
ValueError: invalid literal for int() with base 10: 'saves1023'
2020-07-28 22:19:04,696 INFO: Recipe App startup [in /Users/jacquelynchow/personalprojects/recipe-scraper/app/__init__.py:63]
2020-07-28 22:23:02,169 INFO: Recipe App startup [in /Users/jacquelynchow/personalprojects/recipe-scraper/app/__init__.py:63]
2020-07-28 22:23:26,807 INFO: Recipe App startup [in /Users/jacquelynchow/personalprojects/recipe-scraper/app/__init__.py:63]
2020-07-28 22:23:52,842 ERROR: Exception on /saves [POST] [in /Library/Frameworks/Python.framework/Versions/3.8/lib/python3.8/site-packages/flask/app.py:1891]
Traceback (most recent call last):
  File "/Library/Frameworks/Python.framework/Versions/3.8/lib/python3.8/site-packages/flask/app.py", line 2447, in wsgi_app
    response = self.full_dispatch_request()
  File "/Library/Frameworks/Python.framework/Versions/3.8/lib/python3.8/site-packages/flask/app.py", line 1952, in full_dispatch_request
    rv = self.handle_user_exception(e)
  File "/Library/Frameworks/Python.framework/Versions/3.8/lib/python3.8/site-packages/flask/app.py", line 1821, in handle_user_exception
    reraise(exc_type, exc_value, tb)
  File "/Library/Frameworks/Python.framework/Versions/3.8/lib/python3.8/site-packages/flask/_compat.py", line 39, in reraise
    raise value
  File "/Library/Frameworks/Python.framework/Versions/3.8/lib/python3.8/site-packages/flask/app.py", line 1950, in full_dispatch_request
    rv = self.dispatch_request()
  File "/Library/Frameworks/Python.framework/Versions/3.8/lib/python3.8/site-packages/flask/app.py", line 1936, in dispatch_request
    return self.view_functions[rule.endpoint](**req.view_args)
  File "/Library/Frameworks/Python.framework/Versions/3.8/lib/python3.8/site-packages/flask_login/utils.py", line 272, in decorated_view
    return func(*args, **kwargs)
  File "/Users/jacquelynchow/personalprojects/recipe-scraper/app/routes.py", line 193, in saves
    recipe = Recipe.query.filter_by(id=int(recipeID)).first_or_404()
ValueError: invalid literal for int() with base 10: 'saves1028'
2020-07-28 22:23:55,322 ERROR: Exception on /saves [POST] [in /Library/Frameworks/Python.framework/Versions/3.8/lib/python3.8/site-packages/flask/app.py:1891]
Traceback (most recent call last):
  File "/Library/Frameworks/Python.framework/Versions/3.8/lib/python3.8/site-packages/flask/app.py", line 2447, in wsgi_app
    response = self.full_dispatch_request()
  File "/Library/Frameworks/Python.framework/Versions/3.8/lib/python3.8/site-packages/flask/app.py", line 1952, in full_dispatch_request
    rv = self.handle_user_exception(e)
  File "/Library/Frameworks/Python.framework/Versions/3.8/lib/python3.8/site-packages/flask/app.py", line 1821, in handle_user_exception
    reraise(exc_type, exc_value, tb)
  File "/Library/Frameworks/Python.framework/Versions/3.8/lib/python3.8/site-packages/flask/_compat.py", line 39, in reraise
    raise value
  File "/Library/Frameworks/Python.framework/Versions/3.8/lib/python3.8/site-packages/flask/app.py", line 1950, in full_dispatch_request
    rv = self.dispatch_request()
  File "/Library/Frameworks/Python.framework/Versions/3.8/lib/python3.8/site-packages/flask/app.py", line 1936, in dispatch_request
    return self.view_functions[rule.endpoint](**req.view_args)
  File "/Library/Frameworks/Python.framework/Versions/3.8/lib/python3.8/site-packages/flask_login/utils.py", line 272, in decorated_view
    return func(*args, **kwargs)
  File "/Users/jacquelynchow/personalprojects/recipe-scraper/app/routes.py", line 193, in saves
    recipe = Recipe.query.filter_by(id=int(recipeID)).first_or_404()
ValueError: invalid literal for int() with base 10: 'saves1028'
