2020-07-26 17:15:10,486 ERROR: Exception on /saves [POST] [in /Library/Frameworks/Python.framework/Versions/3.8/lib/python3.8/site-packages/flask/app.py:1891]
Traceback (most recent call last):
  File "/Library/Frameworks/Python.framework/Versions/3.8/lib/python3.8/site-packages/sqlalchemy/orm/sync.py", line 114, in populate_dict
    value = source_mapper._get_state_attr_by_column(
  File "/Library/Frameworks/Python.framework/Versions/3.8/lib/python3.8/site-packages/sqlalchemy/orm/mapper.py", line 2825, in _get_state_attr_by_column
    prop = self._columntoproperty[column]
  File "/Library/Frameworks/Python.framework/Versions/3.8/lib/python3.8/site-packages/sqlalchemy/orm/mapper.py", line 3428, in __missing__
    raise orm_exc.UnmappedColumnError(
sqlalchemy.orm.exc.UnmappedColumnError: No column users.id is configured on mapper mapped class Recipe->recipes...

The above exception was the direct cause of the following exception:

Traceback (most recent call last):
  File "/Library/Frameworks/Python.framework/Versions/3.8/lib/python3.8/site-packages/flask/app.py", line 2447, in wsgi_app
    response = self.full_dispatch_request()
  File "/Library/Frameworks/Python.framework/Versions/3.8/lib/python3.8/site-packages/flask/app.py", line 1952, in full_dispatch_request
    rv = self.handle_user_exception(e)
  File "/Library/Frameworks/Python.framework/Versions/3.8/lib/python3.8/site-packages/flask/app.py", line 1821, in handle_user_exception
    reraise(exc_type, exc_value, tb)
  File "/Library/Frameworks/Python.framework/Versions/3.8/lib/python3.8/site-packages/flask/_compat.py", line 39, in reraise
    raise value
  File "/Library/Frameworks/Python.framework/Versions/3.8/lib/python3.8/site-packages/flask/app.py", line 1950, in full_dispatch_request
    rv = self.dispatch_request()
  File "/Library/Frameworks/Python.framework/Versions/3.8/lib/python3.8/site-packages/flask/app.py", line 1936, in dispatch_request
    return self.view_functions[rule.endpoint](**req.view_args)
  File "/Library/Frameworks/Python.framework/Versions/3.8/lib/python3.8/site-packages/flask_login/utils.py", line 272, in decorated_view
    return func(*args, **kwargs)
  File "/Users/jacquelynchow/personalprojects/recipe-scraper/app/routes.py", line 195, in saves
    db.session.commit()
  File "/Library/Frameworks/Python.framework/Versions/3.8/lib/python3.8/site-packages/sqlalchemy/orm/scoping.py", line 163, in do
    return getattr(self.registry(), name)(*args, **kwargs)
  File "/Library/Frameworks/Python.framework/Versions/3.8/lib/python3.8/site-packages/sqlalchemy/orm/session.py", line 1042, in commit
    self.transaction.commit()
  File "/Library/Frameworks/Python.framework/Versions/3.8/lib/python3.8/site-packages/sqlalchemy/orm/session.py", line 504, in commit
    self._prepare_impl()
  File "/Library/Frameworks/Python.framework/Versions/3.8/lib/python3.8/site-packages/sqlalchemy/orm/session.py", line 483, in _prepare_impl
    self.session.flush()
  File "/Library/Frameworks/Python.framework/Versions/3.8/lib/python3.8/site-packages/sqlalchemy/orm/session.py", line 2523, in flush
    self._flush(objects)
  File "/Library/Frameworks/Python.framework/Versions/3.8/lib/python3.8/site-packages/sqlalchemy/orm/session.py", line 2664, in _flush
    transaction.rollback(_capture_exception=True)
  File "/Library/Frameworks/Python.framework/Versions/3.8/lib/python3.8/site-packages/sqlalchemy/util/langhelpers.py", line 68, in __exit__
    compat.raise_(
  File "/Library/Frameworks/Python.framework/Versions/3.8/lib/python3.8/site-packages/sqlalchemy/util/compat.py", line 178, in raise_
    raise exception
  File "/Library/Frameworks/Python.framework/Versions/3.8/lib/python3.8/site-packages/sqlalchemy/orm/session.py", line 2624, in _flush
    flush_context.execute()
  File "/Library/Frameworks/Python.framework/Versions/3.8/lib/python3.8/site-packages/sqlalchemy/orm/unitofwork.py", line 422, in execute
    rec.execute(self)
  File "/Library/Frameworks/Python.framework/Versions/3.8/lib/python3.8/site-packages/sqlalchemy/orm/unitofwork.py", line 540, in execute
    self.dependency_processor.process_saves(uow, states)
  File "/Library/Frameworks/Python.framework/Versions/3.8/lib/python3.8/site-packages/sqlalchemy/orm/dependency.py", line 1130, in process_saves
    if not self._synchronize(
  File "/Library/Frameworks/Python.framework/Versions/3.8/lib/python3.8/site-packages/sqlalchemy/orm/dependency.py", line 1265, in _synchronize
    sync.populate_dict(
  File "/Library/Frameworks/Python.framework/Versions/3.8/lib/python3.8/site-packages/sqlalchemy/orm/sync.py", line 118, in populate_dict
    _raise_col_to_prop(False, source_mapper, l, None, r, err)
  File "/Library/Frameworks/Python.framework/Versions/3.8/lib/python3.8/site-packages/sqlalchemy/orm/sync.py", line 157, in _raise_col_to_prop
    util.raise_(
  File "/Library/Frameworks/Python.framework/Versions/3.8/lib/python3.8/site-packages/sqlalchemy/util/compat.py", line 178, in raise_
    raise exception
sqlalchemy.orm.exc.UnmappedColumnError: Can't execute sync rule for source column 'users.id'; mapper 'mapped class Recipe->recipes' does not map this column.  Try using an explicit `foreign_keys` collection which does not include destination column 'saved_recipes.recipe_id' (or use a viewonly=True relation).
2020-07-26 17:15:11,263 ERROR: Exception on /saves [POST] [in /Library/Frameworks/Python.framework/Versions/3.8/lib/python3.8/site-packages/flask/app.py:1891]
Traceback (most recent call last):
  File "/Library/Frameworks/Python.framework/Versions/3.8/lib/python3.8/site-packages/flask/app.py", line 2447, in wsgi_app
    response = self.full_dispatch_request()
  File "/Library/Frameworks/Python.framework/Versions/3.8/lib/python3.8/site-packages/flask/app.py", line 1952, in full_dispatch_request
    rv = self.handle_user_exception(e)
  File "/Library/Frameworks/Python.framework/Versions/3.8/lib/python3.8/site-packages/flask/app.py", line 1821, in handle_user_exception
    reraise(exc_type, exc_value, tb)
  File "/Library/Frameworks/Python.framework/Versions/3.8/lib/python3.8/site-packages/flask/_compat.py", line 39, in reraise
    raise value
  File "/Library/Frameworks/Python.framework/Versions/3.8/lib/python3.8/site-packages/flask/app.py", line 1950, in full_dispatch_request
    rv = self.dispatch_request()
  File "/Library/Frameworks/Python.framework/Versions/3.8/lib/python3.8/site-packages/flask/app.py", line 1936, in dispatch_request
    return self.view_functions[rule.endpoint](**req.view_args)
  File "/Library/Frameworks/Python.framework/Versions/3.8/lib/python3.8/site-packages/flask_login/utils.py", line 272, in decorated_view
    return func(*args, **kwargs)
  File "/Users/jacquelynchow/personalprojects/recipe-scraper/app/routes.py", line 202, in saves
    return jsonify({'status':'OK', 'id':recipeID, 'action':action})
NameError: name 'jsonify' is not defined
